<mujoco model="mycobot">
  <compiler angle="radian" meshdir="mesh/" autolimits="true"/>
  <statistic meansize="0.0764619" extent="0.528035" center="0.0439066 -0.0331866 0.217075"/>

  <default>
    <default class="mycobot">
      <general dyntype="none" biastype="affine" ctrlrange="-2.8973 2.8973" forcerange="-87 87"/>
      <joint armature="0.1" damping="1" axis="0 0 1" range="-2.8973 2.8973"/>
    </default>
    <default class="visual">
      <geom group="2" type="mesh" contype="0" conaffinity="0"/>
    </default>
    <default class="collision">
      <geom group="3" type="mesh"/>
    </default>

    <default class="gripper">
      <geom group="3" type="mesh"/>
    </default>

  </default>

  <asset>
    <texture type="2d" name="link1" file="mesh/link1/link1.png"/>
    <material name="material0" texture="link1" specular="0.0" shininess="0.25"/>
    <mesh name ="link1" file="link1/link1.obj"/>

    <texture type="2d" name="link2" file="mesh/link2/link2.png"/>
    <material name="material1" texture="link2" specular="0.0" shininess="0.25"/>
    <mesh name ="link2" file="link2/link2.obj"/>

    <texture type="2d" name="link3" file="mesh/link3/link3.png"/>
    <material name="material2" texture="link3" specular="0.0" shininess="0.25"/>
    <mesh name ="link3" file="link3/link3.obj"/>

    <texture type="2d" name="link4" file="mesh/link4/link4.png"/>
    <material name="material3" texture="link4" specular="0.0" shininess="0.25"/>
    <mesh name ="link4" file="link4/link4.obj"/>

    <texture type="2d" name="link5" file="mesh/link5/link5.png"/>
    <material name="material4" texture="link5" specular="0.0" shininess="0.25"/>
    <mesh name ="link5" file="link5/link5.obj"/>

    <texture type="2d" name="link6" file="mesh/link6/link6.png"/>
    <material name="material5" texture="link6" specular="0.0" shininess="0.25"/>
    <mesh name ="link6" file="link6/link6.obj"/>

    <texture type="2d" name="link7" file="mesh/link7/link7.png"/>
    <material name="material6" texture="link7" specular="0.0" shininess="0.25"/>
    <mesh name ="link7" file="link7/link7.obj"/>

    <material name="material_base" specular="0.0" shininess="0.0" rgba="0.800000 0.800000 0.800000 1.000000"/>
    <material name="material_gripper" specular="1.0" shininess="0.0" rgba="1.000000 1.000000 1.000000 1.000000"/>

    <mesh name="gripper_base" file="gripper_base/gripper_base.obj"/>
    <mesh name="gripper_left1" file="gripper_left1/gripper_left1.obj"/>
    <mesh name="gripper_left2" file="gripper_left2/gripper_left2.obj"/>
    <mesh name="gripper_left3" file="gripper_left3/gripper_left3.obj"/>
    <mesh name="gripper_right1" file="gripper_right1/gripper_right1.obj"/>
    <mesh name="gripper_right2" file="gripper_right2/gripper_right2.obj"/>
    <mesh name="gripper_right3" file="gripper_right3/gripper_right3.obj"/>
  </asset>

  <worldbody>
    <body name="link1" childclass="mycobot">
      <inertial pos="0 0 0.035" mass="10"/>
      <geom quat="0.707107 0 0 -0.707107" material="material0" mesh="link1" class="visual"/>
      <geom pos="0 0 -0.01" quat="0.707107 0 0 -0.707107" mesh="link1" class="collision"/> <!-- This is temporary method to avoid collision between link1 and link2  -->

      <body name="link2" pos="0 0 0.13156">
        <inertial pos="0 0 0.06" quat="0.5 0.5 -0.5 0.5" mass="0.2" diaginertia="0.00025 0.000231667 0.000231667"/>
        <joint name="joint1"/>
        <geom pos="0 0 -0.06096" quat="0.707107 0 0 -0.707107" material="material1" mesh="link2" class="visual"/>
        <geom pos="0 0 -0.06096" quat="0.707107 0 0 -0.707107" mesh="link2" class="collision"/>

        <body name="link3" quat="0.5 0.5 0.5 -0.5">
          <inertial pos="0.01 0 0.06" mass="0.4" diaginertia="0.00105083 0.00105083 0.0005"/>
          <joint name="joint2"/>
          <geom pos="0 0 0.03256" quat="0.707107 0 -0.707107 0" material="material2" mesh="link3" class="visual"/>
          <geom pos="0 0 0.03256" quat="0.707107 0 -0.707107 0" mesh="link3" class="collision"/>
          <body name="link4" pos="-0.1104 0 0">
            <inertial pos="-0.01 0 0.05" mass="0.4" diaginertia="0.00105083 0.00105083 0.0005"/>
            <joint name="joint3"/>
            <geom pos="0 0 0.03056" quat="0.707107 0 -0.707107 0" material="material3" mesh="link4" class="visual"/>
            <geom pos="0 0 0.03056" quat="0.707107 0 -0.707107 0" mesh="link4" class="collision"/>
            <body name="link5" pos="-0.096 0 0.06462" quat="0.707107 0 0 -0.707107">
              <inertial pos="0 0 0.05" quat="0.5 0.5 -0.5 0.5" mass="0.2" diaginertia="0.00025 0.000166667 0.000166667"/>
              <joint name="joint4" />
              <geom pos="0 0 -0.03356" quat="0.707107 -0.707107 0 0" material="material4" mesh="link5" class="visual"/>
              <geom pos="0 0 -0.03356" quat="0.707107 -0.707107 0 0" mesh="link5" class="collision"/>
              <body name="link6" pos="0 -0.07318 0" quat="0.5 0.5 -0.5 0.5">
                <inertial pos="0 0 0.037" quat="0.5 0.5 -0.5 0.5" mass="0.5" diaginertia="0.000625 0.0004625 0.0004625"/>
                <joint name="joint5" />
                <geom pos="0 0 -0.038" material="material5" mesh="link6" class="visual"/>
                <geom pos="0 0 -0.038" mesh="link6" class="collision"/>

                <body name="link7" pos="0 0.0456 0" quat="0.707107 -0.707107 0 0">
                  <inertial pos="0 0.0025 0" quat="4.69093e-07 0.707107 -0.707107 4.69093e-07" mass="0.1" diaginertia="2e-05 1.02083e-05 1.02083e-05"/>
                  <joint name="joint6"/>
                  <geom pos="0 0 -0.012" material="material6" mesh="link7" class="visual"/>
                  <geom pos="0 0 -0.012" mesh="link7" class="collision"/>
                  <geom pos="0 0.011934 0.0420982" quat="0.7042 0.710001 0 0" material="material_base" mesh="gripper_base" class="visual"/>
                  <geom pos="0 0.011934 0.0420982" quat="0.7042 0.710001 0 0" mesh="gripper_base" class="gripper"/>
                  <body name="gripper_left3" pos="-0.012 -4.10179e-05 0.0389998" quat="0.7042 0.710001 0 0">
                    <joint name="gripper_base_to_gripper_left3" pos="0 0 0" axis="0 0 1" range="-0.7 0.15"/>
                    <geom pos="0.012 0.0025 -0.012" material="material_gripper" mesh="gripper_left3" class="visual"/>
                    <geom pos="0.012 0.0025 -0.012" mesh="gripper_left3" class="gripper"/>
                  <body name="gripper_left1" pos="-0.027 0.016 0">
                    <joint name="gripper_left3_to_gripper_left1" pos="0 0 0" axis="0 0 1" range="-0.5 0.5"/>
                    <geom pos="0.039 -0.0133 -0.012" material="material_gripper" mesh="gripper_left1" class="visual"/>
                    <geom pos="0.039 -0.0133 -0.012" mesh="gripper_left1" class="gripper"/>
                  </body>
                </body>
                <body name="gripper_left2" pos="-0.005 -0.000221497 0.0609991" quat="0.7042 0.710001 0 0">
                  <joint name="gripper_base_to_gripper_left2" pos="0 0 0" axis="0 0 1" range="-0.8 0.5"/>
                  <geom pos="0.005 -0.0195 -0.012" material="material_gripper" mesh="gripper_left2" class="visual"/>
                  <geom pos="0.005 -0.0195 -0.012" mesh="gripper_left2" class="gripper"/>
                </body>
                <body name="gripper_right3" pos="0.012 -4.10179e-05 0.0389998" quat="0.7042 0.710001 0 0">
                  <joint name="gripper_base_to_gripper_right3" pos="0 0 0" axis="0 0 1" range="-0.15 0.7"/>
                  <geom pos="-0.012 0.0025 -0.012" material="material_gripper" mesh="gripper_right3" class="visual"/>
                  <geom pos="-0.012 0.0025 -0.012" mesh="gripper_right3" class="gripper"/>
                  <body name="gripper_right1" pos="0.027 0.016 0">
                    <joint name="gripper_right3_to_gripper_right1" pos="0 0 0" axis="0 0 1" range="-0.5 0.5"/>
                    <geom pos="-0.039 -0.0133 -0.012" material="material_gripper" mesh="gripper_right1" class="visual"/>
                    <geom pos="-0.039 -0.0133 -0.012" mesh="gripper_right1" class="gripper"/>
                  </body>
                </body>
                <body name="gripper_right2" pos="0.005 -0.000221497 0.0609991" quat="0.7042 0.710001 0 0">
                  <joint name="gripper_base_to_gripper_right2" pos="0 0 0" axis="0 0 1" range="-0.5 0.8"/>
                  <geom pos="-0.005 -0.0195 -0.012" material="material_gripper" mesh="gripper_right2" class="visual"/>
                  <geom pos="-0.005 -0.0195 -0.012" mesh="gripper_right2" class="gripper"/>
                </body>
              </body>
            </body>
          </body>
        </body>
      </body>
    </body>
  </body>
</worldbody>




</mujoco>
