<?xml version="1.0" ?>
<!-- =================================================================================== -->
<!-- |    This document was autogenerated by xacro from mycobot_urdf.urdf              | -->
<!-- |    EDITING THIS FILE BY HAND IS NOT RECOMMENDED                                 | -->
<!-- =================================================================================== -->
<robot name="firefighter">
  <link name="joint1">
    <visual>
      <geometry>
        <!--- 0.0 0 -0.04  1.5708 3.14159-->
        <mesh filename="package://mycobot_description/urdf/mycobot/joint1.dae"/>
      </geometry>
      <origin rpy=" 0 0 -1.5708" xyz="0.0 0 0 "/>
    </visual>
    <collision>
      <geometry>
        <!--- 0.0 0 -0.04  1.5708 3.14159-->
        <mesh filename="package://mycobot_description/urdf/mycobot/joint1.dae"/>
      </geometry>
      <origin rpy=" 0 0 -1.5708" xyz="0.0 0 0 "/>
    </collision>
  </link>
  <link name="joint2">
    <visual>
      <geometry>
        <mesh filename="package://mycobot_description/urdf/mycobot/joint2.dae"/>
      </geometry>
      <origin rpy=" 0 0 -1.5708" xyz="0.0 0 -0.06096 "/>
    </visual>
    <collision>
      <geometry>
        <mesh filename="package://mycobot_description/urdf/mycobot/joint2.dae"/>
      </geometry>
      <origin rpy=" 0 0 -1.5708" xyz="0.0 0 -0.06096 "/>
    </collision>
  </link>
  <link name="joint3">
    <visual>
      <geometry>
        <mesh filename="package://mycobot_description/urdf/mycobot/joint3.dae"/>
      </geometry>
      <origin rpy=" 0 -1.5708 0" xyz="0.0 0 0.03256 "/>
    </visual>
    <collision>
      <geometry>
        <mesh filename="package://mycobot_description/urdf/mycobot/joint3.dae"/>
      </geometry>
      <origin rpy=" 0 -1.5708 0" xyz="0.0 0 0.03256 "/>
    </collision>
  </link>
  <link name="joint4">
    <visual>
      <geometry>
        <!--- 0.0 0 -0.04 -->
        <mesh filename="package://mycobot_description/urdf/mycobot/joint4.dae"/>
      </geometry>
      <origin rpy=" 0 -1.5708 0" xyz="0.0 0 0.03056 "/>
    </visual>
    <collision>
      <geometry>
        <!--- 0.0 0 -0.04 -->
        <mesh filename="package://mycobot_description/urdf/mycobot/joint4.dae"/>
      </geometry>
      <origin rpy=" 0 -1.5708 0" xyz="0.0 0 0.03056 "/>
    </collision>
  </link>
  <link name="joint5">
    <visual>
      <geometry>
        <!--- 0.0 0 -0.04 -->
        <mesh filename="package://mycobot_description/urdf/mycobot/joint5.dae"/>
      </geometry>
      <origin rpy=" -1.5708 0 0" xyz="0.0 0 -0.03356 "/>
    </visual>
    <collision>
      <geometry>
        <!--- 0.0 0 -0.04 -->
        <mesh filename="package://mycobot_description/urdf/mycobot/joint5.dae"/>
      </geometry>
      <origin rpy=" -1.5708 0 0" xyz="0.0 0 -0.03356 "/>
    </collision>
  </link>
  <link name="joint6">
    <visual>
      <geometry>
        <!--- 0.0 0 -0.04 -->
        <mesh filename="package://mycobot_description/urdf/mycobot/joint6.dae"/>
      </geometry>
      <origin rpy=" 0 0 0" xyz="0 0.00 -0.038 "/>
    </visual>
    <collision>
      <geometry>
        <!--- 0.0 0 -0.04 -->
        <mesh filename="package://mycobot_description/urdf/mycobot/joint6.dae"/>
      </geometry>
      <origin rpy=" 0 0 0" xyz="0 0.00 -0.038 "/>
    </collision>
  </link>
  <link name="joint6_flange">
    <visual>
      <geometry>
        <!--- 0.0 0 -0.04 -->
        <mesh filename="package://mycobot_description/urdf/mycobot/joint7.dae"/>
      </geometry>
      <origin rpy=" 0 0 0" xyz="0.0 0 -0.012 "/>
    </visual>
    <collision>
      <geometry>
        <!--- 0.0 0 -0.04 -->
        <mesh filename="package://mycobot_description/urdf/mycobot/joint7.dae"/>
      </geometry>
      <origin rpy=" 0 0 0" xyz="0.0 0 -0.012 "/>
    </collision>
  </link>
  <joint name="joint2_to_joint1" type="revolute">
    <axis xyz="0 0 1"/>
    <limit effort="1000.0" lower="-3.14" upper="3.14159" velocity="0"/>
    <parent link="joint1"/>
    <child link="joint2"/>
    <origin rpy="0 0 0" xyz="0 0 0.13156"/>
  </joint>
  <joint name="joint3_to_joint2" type="revolute">
    <axis xyz="0 0 1"/>
    <limit effort="1000.0" lower="-3.14" upper="3.14159" velocity="0"/>
    <parent link="joint2"/>
    <child link="joint3"/>
    <origin rpy="0 1.5708 -1.5708" xyz="0 0  0"/>
  </joint>
  <joint name="joint4_to_joint3" type="revolute">
    <axis xyz=" 0 0 1"/>
    <limit effort="1000.0" lower="-3.14" upper="3.14159" velocity="0"/>
    <parent link="joint3"/>
    <child link="joint4"/>
    <origin rpy="0 0 0" xyz="  -0.1104 0 0   "/>
  </joint>
  <joint name="joint5_to_joint4" type="revolute">
    <axis xyz=" 0 0 1"/>
    <limit effort="1000.0" lower="-3.14" upper="3.14159" velocity="0"/>
    <parent link="joint4"/>
    <child link="joint5"/>
    <origin rpy="0 0 -1.5708" xyz="-0.096 0 0.06462"/>
  </joint>
  <joint name="joint6_to_joint5" type="revolute">
    <axis xyz="0 0 1"/>
    <limit effort="1000.0" lower="-3.14" upper="3.14159" velocity="0"/>
    <parent link="joint5"/>
    <child link="joint6"/>
    <origin rpy="1.5708 -1.5708 0" xyz="0 -0.07318 0"/>
  </joint>
  <joint name="joint6output_to_joint6" type="revolute">
    <axis xyz="0 0 1"/>
    <limit effort="1000.0" lower="-3.14" upper="3.14159" velocity="0"/>
    <parent link="joint6"/>
    <child link="joint6_flange"/>
    <origin rpy="-1.5708 0 0" xyz="0 0.0456 0"/>
  </joint>
</robot>

