<mujoco model="mycobot">
  <compiler angle="radian" meshdir="mesh/" autolimits="true"/>
  <statistic meansize="0.0761384" extent="0.52797" center="0.0399067 -0.0331866 0.217042"/>

  <default>
    <default class="mycobot">
      <general dyntype="none" biastype="affine" ctrlrange="-2.8973 2.8973" forcerange="-87 87"/>
      <joint armature="0.1" damping="1" axis="0 0 1" range="-2.8973 2.8973"/>
    </default>
    <default class="visual">
      <geom group="2" type="mesh" contype="0" conaffinity="0"/>
    </default>
    <default class="collision">
      <geom group="3" type="mesh"/>
    </default>

    <default class="gripper">
      <geom group="3" type="mesh"/>
    </default>

    <default class="follower">
      <joint range="-0.872664 0.872664" pos="0 -0.018 0.0065" solimplimit="0.95 0.99 0.001" solreflimit="0.005 1"/>
    </default>
    <default class="gripper_actuator">
      <general biastype="affine"/>

    </default>
  </default>

  <asset>
    <texture type="2d" name="link1" file="mesh/link1/link1.png"/>
    <material name="material0" texture="link1" specular="0.0" shininess="0.25"/>
    <mesh name ="link1" file="link1/link1.obj"/>

    <texture type="2d" name="link2" file="mesh/link2/link2.png"/>
    <material name="material1" texture="link2" specular="0.0" shininess="0.25"/>
    <mesh name ="link2" file="link2/link2.obj"/>

    <texture type="2d" name="link3" file="mesh/link3/link3.png"/>
    <material name="material2" texture="link3" specular="0.0" shininess="0.25"/>
    <mesh name ="link3" file="link3/link3.obj"/>

    <texture type="2d" name="link4" file="mesh/link4/link4.png"/>
    <material name="material3" texture="link4" specular="0.0" shininess="0.25"/>
    <mesh name ="link4" file="link4/link4.obj"/>

    <texture type="2d" name="link5" file="mesh/link5/link5.png"/>
    <material name="material4" texture="link5" specular="0.0" shininess="0.25"/>
    <mesh name ="link5" file="link5/link5.obj"/>

    <texture type="2d" name="link6" file="mesh/link6/link6.png"/>
    <material name="material5" texture="link6" specular="0.0" shininess="0.25"/>
    <mesh name ="link6" file="link6/link6.obj"/>

    <texture type="2d" name="link7" file="mesh/link7/link7.png"/>
    <material name="material6" texture="link7" specular="0.0" shininess="0.25"/>
    <mesh name ="link7" file="link7/link7.obj"/>

    <material name="material_base" specular="0.0" shininess="0.0" rgba="0.800000 0.800000 0.800000 1.000000"/>
    <material name="material_gripper" specular="1.0" shininess="0.0" rgba="1.000000 1.000000 1.000000 1.000000"/>

    <mesh name="gripper_base" file="gripper_base/gripper_base.obj"/>
    <mesh name="gripper_left1" file="gripper_left1/gripper_left1.obj"/>
    <mesh name="gripper_left2" file="gripper_left2/gripper_left2.obj"/>
    <mesh name="gripper_left3" file="gripper_left3/gripper_left3.obj"/>
    <mesh name="gripper_right1" file="gripper_right1/gripper_right1.obj"/>
    <mesh name="gripper_right2" file="gripper_right2/gripper_right2.obj"/>
    <mesh name="gripper_right3" file="gripper_right3/gripper_right3.obj"/>
  </asset>


  <worldbody>


    <body name="link1" childclass="mycobot">
      <inertial pos="0 0 0.035" mass="10"/>
      <geom quat="0.707107 0 0 -0.707107" material="material0" mesh="link1" class="visual"/>
      <geom pos="0 0 -0.01" quat="0.707107 0 0 -0.707107" mesh="link1" class="collision"/> <!-- This is temporary method to avoid collision between link1 and link2  -->

      <body name="link2" pos="0 0 0.13156">
        <inertial pos="0 0 0.06" quat="0.5 0.5 -0.5 0.5" mass="0.2" diaginertia="0.00025 0.000231667 0.000231667"/>
        <joint name="joint1"/>
        <geom pos="0 0 -0.06096" quat="0.707107 0 0 -0.707107" material="material1" mesh="link2" class="visual"/>
        <geom pos="0 0 -0.06096" quat="0.707107 0 0 -0.707107" mesh="link2" class="collision"/>

        <body name="link3" quat="0.5 0.5 0.5 -0.5">
          <inertial pos="0.01 0 0.06" mass="0.4" diaginertia="0.00105083 0.00105083 0.0005"/>
          <joint name="joint2"/>
          <geom pos="0 0 0.03256" quat="0.707107 0 -0.707107 0" material="material2" mesh="link3" class="visual"/>
          <geom pos="0 0 0.03256" quat="0.707107 0 -0.707107 0" mesh="link3" class="collision"/>
          <body name="link4" pos="-0.1104 0 0">
            <inertial pos="-0.01 0 0.05" mass="0.4" diaginertia="0.00105083 0.00105083 0.0005"/>
            <joint name="joint3"/>
            <geom pos="0 0 0.03056" quat="0.707107 0 -0.707107 0" material="material3" mesh="link4" class="visual"/>
            <geom pos="0 0 0.03056" quat="0.707107 0 -0.707107 0" mesh="link4" class="collision"/>
            <body name="link5" pos="-0.096 0 0.06462" quat="0.707107 0 0 -0.707107">
              <inertial pos="0 0 0.05" quat="0.5 0.5 -0.5 0.5" mass="0.2" diaginertia="0.00025 0.000166667 0.000166667"/>
              <joint name="joint4" />
              <geom pos="0 0 -0.03356" quat="0.707107 -0.707107 0 0" material="material4" mesh="link5" class="visual"/>
              <geom pos="0 0 -0.03356" quat="0.707107 -0.707107 0 0" mesh="link5" class="collision"/>
              <body name="link6" pos="0 -0.07318 0" quat="0.5 0.5 -0.5 0.5">
                <inertial pos="0 0 0.037" quat="0.5 0.5 -0.5 0.5" mass="0.5" diaginertia="0.000625 0.0004625 0.0004625"/>
                <joint name="joint5" />
                <geom pos="0 0 -0.038" material="material5" mesh="link6" class="visual"/>
                <geom pos="0 0 -0.038" mesh="link6" class="collision"/>

                <body name="link7" pos="0 0.0456 0" quat="0.707107 -0.707107 0 0">
                  <inertial pos="0 0.0025 0" quat="4.69093e-07 0.707107 -0.707107 4.69093e-07" mass="0.1" diaginertia="2e-05 1.02083e-05 1.02083e-05"/>
                  <joint name="joint6"/>
                  <geom pos="0 0 -0.012" material="material6" mesh="link7" class="visual"/>
                  <geom pos="0 0 -0.012" mesh="link7" class="collision"/>
                  <body name="gripper_base">
                    <geom pos="0 0.0119996 0.0340984" quat="0.7042 0.710001 0 0" material="material_gripper" class="visual" mesh="gripper_base"/>
                    <geom pos="0 0.0119996 0.0340984" quat="0.7042 0.710001 0 0" class="gripper" mesh="gripper_base"/>
                    <body name="gripper_left3" pos="-0.012 2.46107e-05 0.0310001" quat="0.7042 0.710001 0 0">
                      <joint name="gripper_base_to_gripper_left3" pos="0 0 0" axis="0 0 1" range="-0.7 0.15"/>
                      <geom pos="0.012 0.0033 -0.012" material="material_gripper" class="visual" mesh="gripper_left3"/>
                      <geom pos="0.012 0.0033 -0.012" class="gripper" mesh="gripper_left3"/>

                    </body>
                    <body name="gripper_left2" pos="-0.005 -0.000155868 0.0529994" quat="0.7042 0.710001 0 0">
                      <joint name="gripper_base_to_gripper_left2" pos="0 0 0" axis="0 0 1" range="-0.8 0.5"/>
                      <geom pos="0.005 -0.0195 -0.012" material="material_gripper" class="visual" mesh="gripper_left2"/>
                      <geom pos="0.005 -0.0195 -0.012" class="gripper" mesh="gripper_left2"/>
                      <body name="gripper_left1" pos="-0.034 -0.0065 0">
                        <joint name="gripper_left2_to_gripper_left1" pos="0.0072 0.022 0" axis="0 0 1" range="-0.5 0.7"/>
                        <geom pos="0.039 -0.0133 -0.012"  name="gripper_left1" material="material_gripper" class="visual" mesh="gripper_left1"/>
                        <geom pos="0.039 -0.0133 -0.012" class="gripper" mesh="gripper_left1"/>
                      </body>
                    </body>
                    <body name="gripper_right3" pos="0.012 2.46107e-05 0.0310001" quat="0.7042 0.710001 0 0">
                      <joint name="gripper_base_to_gripper_right3" pos="0 0 0" axis="0 0 1" range="-0.15 0.7"/>
                      <geom pos="-0.012 0.0033 -0.012" material="material_gripper" class="visual" mesh="gripper_right3"/>
                      <geom pos="-0.012 0.0033 -0.012" class="gripper" mesh="gripper_right3"/>

                    </body>
                    <body name="gripper_right2" pos="0.005 -0.000155868 0.0529994" quat="0.7042 0.710001 0 0">
                      <joint name="gripper_base_to_gripper_right2" pos="0 0 0" axis="0 0 1" range="-0.5 0.8"/>
                      <geom pos="-0.005 -0.0195 -0.012" material="material_gripper" class="visual" mesh="gripper_right2"/>
                      <geom pos="-0.005 -0.0195 -0.012" class="gripper" mesh="gripper_right2"/>
                      <body name="gripper_right1" pos="0.034 -0.0065 0">
                        <joint name="gripper_right2_to_gripper_right1" pos="-0.0072 0.022 0" axis="0 0 1" range="-0.7 0.5"/>
                        <geom pos="-0.039 -0.0133 -0.012"  name="gripper_right1" material="material_gripper" class="visual" mesh="gripper_right1"/>
                        <geom pos="-0.039 -0.0133 -0.012" class="gripper" mesh="gripper_right1"/>
                      </body>
                    </body>
                  </body>
                </body>
              </body>
            </body>
          </body>
        </body>
      </body>
    </body>
  </worldbody>

  <contact>
    <exclude body1="gripper_base" body2="gripper_left3"/>
    <exclude body1="gripper_base" body2="gripper_right3"/>
    <exclude body1="gripper_base" body2="gripper_left2"/>
    <exclude body1="gripper_base" body2="gripper_right2"/>
    <exclude body1="gripper_base" body2="gripper_left1"/>
    <exclude body1="gripper_base" body2="gripper_right1"/>

    <exclude body1="gripper_right2" body2="gripper_right1"/>
    <exclude body1="gripper_right2" body2="gripper_right3"/>
    <exclude body1="gripper_right3" body2="gripper_right1"/>
    <exclude body1="gripper_left3" body2="gripper_left1"/>
    <exclude body1="gripper_left2" body2="gripper_left3"/>
    <exclude body1="gripper_left2" body2="gripper_left1"/>

    <exclude body1="gripper_left3" body2="gripper_right3"/>
  </contact>


  <tendon>
    <fixed name="split">
      <joint joint="gripper_base_to_gripper_left3" coef="-0.5"/>
      <joint joint="gripper_base_to_gripper_right3" coef="0.5"/>
    </fixed>
  </tendon>

  <equality>
    <connect anchor="0 0 0" body1="gripper_left1" body2="gripper_left3" solimp="0.95 0.99 0.001" solref="0.005 1"/>
    <connect anchor="0 0 0" body1="gripper_right1" body2="gripper_right3" solimp="0.95 0.99 0.001" solref="0.005 1"/>
    <!-- <joint joint1="gripper_base_to_gripper_left3" joint2="gripper_base_to_gripper_right3" polycoef="0 1 0 0 0" solimp="0.95 0.99 0.001" solref="0.005 1"/> -->
  </equality>

  <actuator>
    <general class="mycobot" name="actuator1" joint="joint1" gainprm="4500" biasprm="0 -4500 -450" ctrlrange="-2.7925 2.7925"/>
    <general class="mycobot" name="actuator2" joint="joint2" gainprm="4500" biasprm="0 -4500 -450" ctrlrange="-2.7925 2.7925"/>
    <general class="mycobot" name="actuator3" joint="joint3" gainprm="3500" biasprm="0 -3500 -350" ctrlrange="-2.7925 2.7925"/>
    <general class="mycobot" name="actuator4" joint="joint4" gainprm="3500" biasprm="0 -3500 -350" ctrlrange="-2.7925 2.7925"/>
    <general class="mycobot" name="actuator5" joint="joint5" gainprm="2000" biasprm="0 -2000 -200" ctrlrange="-2.7925 2.7925"/>
    <general class="mycobot" name="actuator6" joint="joint6" gainprm="2000" biasprm="0 -2000 -200" ctrlrange="-2.7925 2.7925"/>
    <general class="gripper_actuator" name="gripper_actuator" tendon="split" forcerange="-50 50" ctrlrange="0 1" gainprm="100.3137255 0 0" biasprm="0 -100 -10"/>
  </actuator>

</mujoco>
