<?xml version="1.0" ?>
<!-- =================================================================================== -->
<!-- |    This document was autogenerated by xacro from mycobot_with_gripper_parallel.urdf.xacro | -->
<!-- |    EDITING THIS FILE BY HAND IS NOT RECOMMENDED                                 | -->
<!-- =================================================================================== -->
<robot name="mycobot">
  <material name="aluminum">
    <color rgba="0.5 0.5 0.5 1"/>
  </material>
  <material name="plastic">
    <color rgba="0.1 0.1 0.1 1"/>
  </material>
  <!-- camera body, with origin at bottom screw mount -->
  <joint name="camera_joint" type="fixed">
    <origin rpy="0 0 3.141592653589793" xyz="0.68 0.05 0.38"/>
    <parent link="g_base"/>
    <child link="camera_bottom_screw_frame"/>
  </joint>
  <link name="camera_bottom_screw_frame"/>
  <joint name="camera_link_joint" type="fixed">
    <origin rpy="0 0 0" xyz="0.010600000000000002 0.0175 0.0125"/>
    <parent link="camera_bottom_screw_frame"/>
    <child link="camera_link"/>
  </joint>
  <link name="camera_link">
    <visual>
      <!-- the mesh origin is at front plate in between the two infrared camera axes -->
      <origin rpy="1.5707963267948966 0 1.5707963267948966" xyz="0.0043 -0.0175 0"/>
      <geometry>
        <mesh filename="package://realsense2_description/meshes/d435.dae"/>
      </geometry>
    </visual>
    <collision>
      <origin rpy="0 0 0" xyz="0 -0.0175 0"/>
      <geometry>
        <box size="0.02505 0.09 0.025"/>
      </geometry>
    </collision>
    <inertial>
      <!-- The following are not reliable values, and should not be used for modeling -->
      <mass value="0.072"/>
      <origin xyz="0 0 0"/>
      <inertia ixx="0.003881243" ixy="0.0" ixz="0.0" iyy="0.000498940" iyz="0.0" izz="0.003879257"/>
    </inertial>
  </link>
  <link name="g_base">
    <visual>
      <geometry>
        <mesh filename="package://mycobot_description/urdf/mycobot/G_base.dae"/>
      </geometry>
      <origin rpy="0 0 1.5708" xyz="0.0 0 -0.027"/>
    </visual>
    <collision>
      <geometry>
        <mesh filename="package://mycobot_description/urdf/mycobot/G_base.dae"/>
      </geometry>
      <origin rpy="0 0 1.5708" xyz="0.0 0 -0.027"/>
    </collision>
  </link>
  <link name="link1">
    <inertial>
      <origin rpy="0 0 0" xyz="0 0 0.035"/>
      <mass value="10.0"/>
      <inertia ixx="0.010333333333333335" ixy="0" ixz="0" iyy="0.010333333333333335" iyz="0" izz="0.0125"/>
    </inertial>
    <visual>
      <geometry>
        <mesh filename="package://mycobot_description/urdf/mycobot/mesh/link1.dae"/>
      </geometry>
      <origin rpy=" 0 0 -1.5707963267948966" xyz="0.0 0 0 "/>
    </visual>
    <collision>
      <geometry>
        <mesh filename="package://mycobot_description/urdf/mycobot/mesh/link1.dae"/>
      </geometry>
      <origin rpy=" 0 0 -1.5707963267948966" xyz="0.0 0 0 "/>
    </collision>
  </link>
  <link name="link2">
    <inertial>
      <origin rpy="0 0 0" xyz="0 0 0.060"/>
      <mass value="0.2"/>
      <inertia ixx="0.00023166666666666672" ixy="0" ixz="0" iyy="0.00023166666666666672" iyz="0" izz="0.00025000000000000006"/>
    </inertial>
    <visual>
      <geometry>
        <mesh filename="package://mycobot_description/urdf/mycobot/mesh/link2.dae"/>
      </geometry>
      <origin rpy=" 0 0 -1.5707963267948966" xyz="0.0 0 -0.06096 "/>
    </visual>
    <collision>
      <geometry>
        <mesh filename="package://mycobot_description/urdf/mycobot/mesh/link2.dae"/>
      </geometry>
      <origin rpy=" 0 0 -1.5707963267948966" xyz="0.0 0 -0.06096 "/>
    </collision>
  </link>
  <link name="link3">
    <inertial>
      <origin rpy="0 0 0" xyz="0.01 0 0.06"/>
      <mass value="0.4"/>
      <inertia ixx="0.0010508333333333335" ixy="0" ixz="0" iyy="0.0010508333333333335" iyz="0" izz="0.0005000000000000001"/>
    </inertial>
    <visual>
      <geometry>
        <mesh filename="package://mycobot_description/urdf/mycobot/mesh/link3.dae"/>
      </geometry>
      <origin rpy=" 0 -1.5707963267948966 0" xyz="0.0 0 0.03256 "/>
    </visual>
    <collision>
      <geometry>
        <mesh filename="package://mycobot_description/urdf/mycobot/mesh/link3.dae"/>
      </geometry>
      <origin rpy=" 0 -1.5707963267948966 0" xyz="0.0 0 0.03256 "/>
    </collision>
  </link>
  <link name="link4">
    <inertial>
      <origin rpy="0 0 0" xyz="-0.01 0 0.05"/>
      <mass value="0.4"/>
      <inertia ixx="0.0010508333333333335" ixy="0" ixz="0" iyy="0.0010508333333333335" iyz="0" izz="0.0005000000000000001"/>
    </inertial>
    <visual>
      <geometry>
        <!--- 0.0 0 -0.04 -->
        <mesh filename="package://mycobot_description/urdf/mycobot/mesh/link4.dae"/>
      </geometry>
      <origin rpy=" 0 -1.5707963267948966 0" xyz="0.0 0 0.03056 "/>
    </visual>
    <collision>
      <geometry>
        <!--- 0.0 0 -0.04 -->
        <mesh filename="package://mycobot_description/urdf/mycobot/mesh/link4.dae"/>
      </geometry>
      <origin rpy=" 0 -1.5707963267948966 0" xyz="0.0 0 0.03056 "/>
    </collision>
  </link>
  <link name="link5">
    <inertial>
      <origin rpy="0 0 0" xyz="0 0 0.05"/>
      <mass value="0.2"/>
      <inertia ixx="0.00016666666666666672" ixy="0" ixz="0" iyy="0.00016666666666666672" iyz="0" izz="0.00025000000000000006"/>
    </inertial>
    <visual>
      <geometry>
        <!--- 0.0 0 -0.04 -->
        <mesh filename="package://mycobot_description/urdf/mycobot/mesh/link5.dae"/>
      </geometry>
      <origin rpy=" -1.5707963267948966 0 0" xyz="0.0 0 -0.03356 "/>
    </visual>
    <collision>
      <geometry>
        <!--- 0.0 0 -0.04 -->
        <mesh filename="package://mycobot_description/urdf/mycobot/mesh/link5.dae"/>
      </geometry>
      <origin rpy=" -1.5707963267948966 0 0" xyz="0.0 0 -0.03356 "/>
    </collision>
  </link>
  <link name="link6">
    <inertial>
      <origin rpy="0 0 0" xyz="0 0 0.037"/>
      <mass value="0.5"/>
      <inertia ixx="0.0004625000000000001" ixy="0" ixz="0" iyy="0.0004625000000000001" iyz="0" izz="0.0006250000000000001"/>
    </inertial>
    <visual>
      <geometry>
        <!--- 0.0 0 -0.04 -->
        <mesh filename="package://mycobot_description/urdf/mycobot/mesh/link6.dae"/>
      </geometry>
      <origin rpy=" 0 0 0" xyz="0 0.00 -0.038 "/>
    </visual>
    <collision>
      <geometry>
        <!--- 0.0 0 -0.04 -->
        <mesh filename="package://mycobot_description/urdf/mycobot/mesh/link6.dae"/>
      </geometry>
      <origin rpy=" 0 0 0" xyz="0 0.00 -0.038 "/>
    </collision>
  </link>
  <link name="link7">
    <inertial>
      <origin rpy="1.570795 0 0" xyz="0 0.0025 0"/>
      <mass value="0.1"/>
      <inertia ixx="1.0208333333333334e-05" ixy="0" ixz="0" iyy="1.0208333333333334e-05" iyz="0" izz="2e-05"/>
    </inertial>
    <visual>
      <geometry>
        <!--- 0.0 0 -0.04 -->
        <mesh filename="package://mycobot_description/urdf/mycobot/mesh/link7.dae"/>
      </geometry>
      <origin rpy=" 0 0 0" xyz="0.0 0 -0.012 "/>
    </visual>
    <collision>
      <geometry>
        <!--- 0.0 0 -0.04 -->
        <mesh filename="package://mycobot_description/urdf/mycobot/mesh/link7.dae"/>
      </geometry>
      <origin rpy=" 0 0 0" xyz="0.0 0 -0.012 "/>
    </collision>
  </link>
  <joint name="joint1" type="revolute">
    <axis xyz="0 0 1"/>
    <limit effort="10.0" lower="-3.141592653589793" upper="3.141592653589793" velocity="1.0"/>
    <parent link="link1"/>
    <child link="link2"/>
    <origin rpy="0 0 0" xyz="0 0 0.13156"/>
    <dynamics damping="1.0e-6" friction="2.0e-1"/>
  </joint>
  <joint name="joint2" type="revolute">
    <axis xyz="0 0 1"/>
    <limit effort="10.0" lower="-3.141592653589793" upper="3.141592653589793" velocity="1.0"/>
    <parent link="link2"/>
    <child link="link3"/>
    <origin rpy="0 1.5707963267948966 -1.5707963267948966" xyz="0 0  0"/>
    <dynamics damping="1.0e-6" friction="2.0e-1"/>
  </joint>
  <joint name="joint3" type="revolute">
    <axis xyz=" 0 0 1"/>
    <limit effort="10.0" lower="-3.141592653589793" upper="3.141592653589793" velocity="1.0"/>
    <parent link="link3"/>
    <child link="link4"/>
    <origin rpy="0 0 0" xyz="-0.1104 0 0   "/>
    <dynamics damping="1.0e-6" friction="2.0e-1"/>
  </joint>
  <joint name="joint4" type="revolute">
    <axis xyz=" 0 0 1"/>
    <limit effort="10.0" lower="-3.141592653589793" upper="3.141592653589793" velocity="1.0"/>
    <parent link="link4"/>
    <child link="link5"/>
    <origin rpy="0 0 -1.5707963267948966" xyz="-0.096 0 0.06462"/>
    <dynamics damping="1.0e-6" friction="2.0e-1"/>
  </joint>
  <joint name="joint5" type="revolute">
    <axis xyz="0 0 1"/>
    <limit effort="10.0" lower="-3.141592653589793" upper="3.141592653589793" velocity="1.0"/>
    <parent link="link5"/>
    <child link="link6"/>
    <origin rpy="1.5707963267948966 -1.5707963267948966 0" xyz="0 -0.07318 0"/>
    <dynamics damping="1.0e-6" friction="2.0e-1"/>
  </joint>
  <joint name="joint6" type="revolute">
    <axis xyz="0 0 1"/>
    <limit effort="10.0" lower="-3.141592653589793" upper="3.141592653589793" velocity="1.0"/>
    <parent link="link6"/>
    <child link="link7"/>
    <origin rpy="-1.5707963267948966 0 0" xyz="0 0.0456 0"/>
    <dynamics damping="1.0e-6" friction="2.0e-1"/>
  </joint>
  <link name="gripper_base">
    <visual>
      <geometry>
        <!--- 0.0 0 -0.04 -->
        <mesh filename="package://mycobot_description/urdf/mycobot/gripper_base.dae"/>
      </geometry>
      <origin rpy=" 0 0 0" xyz="0.0 0 -0.012 "/>
    </visual>
    <collision>
      <geometry>
        <!--- 0.0 0 -0.04 -->
        <mesh filename="package://mycobot_description/urdf/mycobot/gripper_base.dae"/>
      </geometry>
      <origin rpy=" 0 0 0" xyz="0.0 0 -0.012 "/>
    </collision>
  </link>
  <link name="gripper_left1">
    <visual>
      <geometry>
        <!--- 0.0 0 -0.04 -->
        <mesh filename="package://mycobot_description/urdf/mycobot/gripper_left1.dae"/>
      </geometry>
      <origin rpy=" 0 0 0" xyz="0.039 -0.0133 -0.012 "/>
      <!-- <origin xyz = "0.0 0 -0.012 " rpy = " 0 0 0"/> -->
    </visual>
    <collision>
      <geometry>
        <mesh filename="package://mycobot_description/urdf/mycobot/gripper_left1.dae"/>
      </geometry>
      <origin rpy=" 0 0 0" xyz="-0.039 -0.0133 -0.012 "/>
    </collision>
  </link>
  <link name="gripper_left2">
    <visual>
      <geometry>
        <mesh filename="package://mycobot_description/urdf/mycobot/gripper_left2.dae"/>
      </geometry>
      <origin rpy=" 0 0 0" xyz="0.005 -0.0195 -0.012 "/>
    </visual>
    <collision>
      <geometry>
        <mesh filename="package://mycobot_description/urdf/mycobot/gripper_left2.dae"/>
      </geometry>
      <origin rpy=" 0 0 0" xyz="-0.005 -0.0195 -0.012 "/>
    </collision>
  </link>
  <link name="gripper_left3">
    <visual>
      <geometry>
        <mesh filename="package://mycobot_description/urdf/mycobot/gripper_left3.dae"/>
      </geometry>
      <origin rpy=" 0 0 0" xyz="0.012 0.0025 -0.012 "/>
      <!-- <origin xyz = "0.0 0 0 " rpy = " 0 0 0"/> -->
    </visual>
    <collision>
      <geometry>
        <mesh filename="package://mycobot_description/urdf/mycobot/gripper_left3.dae"/>
      </geometry>
      <origin rpy=" 0 0 0" xyz="0.0 0 -0.012 "/>
    </collision>
  </link>
  <link name="gripper_right1">
    <visual>
      <geometry>
        <mesh filename="package://mycobot_description/urdf/mycobot/gripper_right1.dae"/>
      </geometry>
      <origin rpy=" 0 0 0" xyz="-0.039 -0.0133 -0.012 "/>
    </visual>
    <collision>
      <geometry>
        <mesh filename="package://mycobot_description/urdf/mycobot/gripper_right1.dae"/>
      </geometry>
      <origin rpy=" 0 0 0" xyz="-0.039 -0.0133 -0.012 "/>
    </collision>
  </link>
  <link name="gripper_right2">
    <visual>
      <geometry>
        <mesh filename="package://mycobot_description/urdf/mycobot/gripper_right2.dae"/>
      </geometry>
      <origin rpy=" 0 0 0" xyz="-0.005 -0.0195 -0.012 "/>
    </visual>
    <collision>
      <geometry>
        <mesh filename="package://mycobot_description/urdf/mycobot/gripper_right2.dae"/>
      </geometry>
      <origin rpy=" 0 0 0" xyz="-0.005 -0.0195 -0.012 "/>
    </collision>
  </link>
  <link name="gripper_right3">
    <visual>
      <geometry>
        <mesh filename="package://mycobot_description/urdf/mycobot/gripper_right3.dae"/>
      </geometry>
      <origin rpy=" 0 0 0" xyz="-0.012 0.0025 -0.012 "/>
    </visual>
    <collision>
      <geometry>
        <mesh filename="package://mycobot_description/urdf/mycobot/gripper_right3.dae"/>
      </geometry>
      <origin rpy=" 0 0 0" xyz="-0.012 0.0025 -0.012"/>
    </collision>
  </link>
  <joint name="g_base_to_link1" type="fixed">
    <axis xyz="0 0 0"/>
    <limit effort="1000.0" lower="-3.14" upper="3.14159" velocity="0"/>
    <parent link="g_base"/>
    <child link="link1"/>
    <origin rpy="0 0 0" xyz="0 0 0"/>
  </joint>
  <joint name="link7_to_gripper_base" type="fixed">
    <!-- <axis xyz="0 0 1"/>
    <limit effort = "1000.0" lower = "-3.14" upper = "3.14159" velocity = "0"/> -->
    <parent link="link7"/>
    <child link="gripper_base"/>
    <!-- <origin xyz= "0 0.0 0" rpy = "-1.5708 0 0"/>   -->
    <origin rpy="1.579 0 0" xyz="0 0 0.034"/>
  </joint>
  <joint name="gripper_controller" type="revolute">
    <axis xyz="0 0 1"/>
    <limit effort="1000.0" lower="-0.7" upper="0.15" velocity="0"/>
    <parent link="gripper_base"/>
    <child link="gripper_left3"/>
    <origin rpy="0 0 0" xyz="-0.012 0.005 0"/>
  </joint>
  <joint name="gripper_base_to_gripper_left2" type="revolute">
    <axis xyz="0 0 1"/>
    <limit effort="1000.0" lower="-0.8" upper="0.5" velocity="0"/>
    <parent link="gripper_base"/>
    <child link="gripper_left2"/>
    <origin rpy="0 0 0" xyz="-0.005 0.027 0"/>
    <mimic joint="gripper_controller" multiplier="1.0" offset="0"/>
  </joint>
  <joint name="gripper_left3_to_gripper_left1" type="revolute">
    <axis xyz="0 0 1"/>
    <limit effort="1000.0" lower="-0.5" upper="0.5" velocity="0"/>
    <parent link="gripper_left3"/>
    <child link="gripper_left1"/>
    <origin rpy="0 0 0" xyz="-0.027 0.016 0"/>
    <mimic joint="gripper_controller" multiplier="-1.0" offset="0"/>
  </joint>
  <joint name="gripper_base_to_gripper_right3" type="revolute">
    <axis xyz="0 0 1"/>
    <limit effort="1000.0" lower="-0.15" upper="0.7" velocity="0"/>
    <parent link="gripper_base"/>
    <child link="gripper_right3"/>
    <origin rpy="0 0 0" xyz="0.012 0.005 0"/>
    <mimic joint="gripper_controller" multiplier="-1.0" offset="0"/>
  </joint>
  <joint name="gripper_base_to_gripper_right2" type="revolute">
    <axis xyz="0 0 1"/>
    <limit effort="1000.0" lower="-0.5" upper="0.8" velocity="0"/>
    <parent link="gripper_base"/>
    <child link="gripper_right2"/>
    <origin rpy="0 0 0" xyz="0.005 0.027 0"/>
    <mimic joint="gripper_controller" multiplier="-1.0" offset="0"/>
  </joint>
  <joint name="gripper_right3_to_gripper_right1" type="revolute">
    <axis xyz="0 0 1"/>
    <limit effort="1000.0" lower="-0.5" upper="0.5" velocity="0"/>
    <parent link="gripper_right3"/>
    <child link="gripper_right1"/>
    <origin rpy="0 0 0" xyz="0.027 0.016 0"/>
    <mimic joint="gripper_controller" multiplier="1.0" offset="0"/>
  </joint>
  <transmission name="joint1_trans">
    <provideFeedback>true</provideFeedback>
    <implicitSpringDamper>0</implicitSpringDamper>
    <motorTorqueConstant>0.418</motorTorqueConstant>
    <type>transmission_interface/SimpleTransmission</type>
    <joint name="joint1">
      <hardwareInterface>hardware_interface/PositionJointInterface</hardwareInterface>
    </joint>
    <actuator name="joint1_motor">
      <hardwareInterface>hardware_interface/PositionJointInterface</hardwareInterface>
      <mechanicalReduction>1</mechanicalReduction>
    </actuator>
  </transmission>
  <transmission name="joint2_trans">
    <provideFeedback>true</provideFeedback>
    <implicitSpringDamper>0</implicitSpringDamper>
    <motorTorqueConstant>0.418</motorTorqueConstant>
    <type>transmission_interface/SimpleTransmission</type>
    <joint name="joint2">
      <hardwareInterface>hardware_interface/PositionJointInterface</hardwareInterface>
    </joint>
    <actuator name="joint2_motor">
      <hardwareInterface>hardware_interface/PositionJointInterface</hardwareInterface>
      <mechanicalReduction>1</mechanicalReduction>
    </actuator>
  </transmission>
  <transmission name="joint3_trans">
    <provideFeedback>true</provideFeedback>
    <implicitSpringDamper>0</implicitSpringDamper>
    <motorTorqueConstant>0.418</motorTorqueConstant>
    <type>transmission_interface/SimpleTransmission</type>
    <joint name="joint3">
      <hardwareInterface>hardware_interface/PositionJointInterface</hardwareInterface>
    </joint>
    <actuator name="joint3_motor">
      <hardwareInterface>hardware_interface/PositionJointInterface</hardwareInterface>
      <mechanicalReduction>1</mechanicalReduction>
    </actuator>
  </transmission>
  <transmission name="joint4_trans">
    <provideFeedback>true</provideFeedback>
    <implicitSpringDamper>0</implicitSpringDamper>
    <motorTorqueConstant>0.418</motorTorqueConstant>
    <type>transmission_interface/SimpleTransmission</type>
    <joint name="joint4">
      <hardwareInterface>hardware_interface/PositionJointInterface</hardwareInterface>
    </joint>
    <actuator name="joint4_motor">
      <hardwareInterface>hardware_interface/PositionJointInterface</hardwareInterface>
      <mechanicalReduction>1</mechanicalReduction>
    </actuator>
  </transmission>
  <transmission name="joint5_trans">
    <provideFeedback>true</provideFeedback>
    <implicitSpringDamper>0</implicitSpringDamper>
    <motorTorqueConstant>0.418</motorTorqueConstant>
    <type>transmission_interface/SimpleTransmission</type>
    <joint name="joint5">
      <hardwareInterface>hardware_interface/PositionJointInterface</hardwareInterface>
    </joint>
    <actuator name="joint5_motor">
      <hardwareInterface>hardware_interface/PositionJointInterface</hardwareInterface>
      <mechanicalReduction>1</mechanicalReduction>
    </actuator>
  </transmission>
  <transmission name="joint6_trans">
    <provideFeedback>true</provideFeedback>
    <implicitSpringDamper>0</implicitSpringDamper>
    <motorTorqueConstant>0.418</motorTorqueConstant>
    <type>transmission_interface/SimpleTransmission</type>
    <joint name="joint6">
      <hardwareInterface>hardware_interface/PositionJointInterface</hardwareInterface>
    </joint>
    <actuator name="joint6_motor">
      <hardwareInterface>hardware_interface/PositionJointInterface</hardwareInterface>
      <mechanicalReduction>1</mechanicalReduction>
    </actuator>
  </transmission>
  <transmission name="link7_to_gripper_base_trans">
    <provideFeedback>true</provideFeedback>
    <type>transmission_interface/SimpleTransmission</type>
    <joint name="link7_to_gripper_base">
      <hardwareInterface>hardware_interface/PositionJointInterface</hardwareInterface>
    </joint>
    <actuator name="link7_to_gripper_base_actuator">
      <hardwareInterface>hardware_interface/PositionJointInterface</hardwareInterface>
      <mechanicalReduction>1</mechanicalReduction>
    </actuator>
  </transmission>
  <transmission name="gripper_controller_trans">
    <provideFeedback>true</provideFeedback>
    <type>transmission_interface/SimpleTransmission</type>
    <joint name="gripper_controller">
      <hardwareInterface>hardware_interface/PositionJointInterface</hardwareInterface>
    </joint>
    <actuator name="gripper_controller_actuator">
      <hardwareInterface>hardware_interface/PositionJointInterface</hardwareInterface>
      <mechanicalReduction>1</mechanicalReduction>
    </actuator>
  </transmission>
  <transmission name="gripper_base_to_gripper_left2_trans">
    <provideFeedback>true</provideFeedback>
    <type>transmission_interface/SimpleTransmission</type>
    <joint name="gripper_base_to_gripper_left2">
      <hardwareInterface>hardware_interface/PositionJointInterface</hardwareInterface>
    </joint>
    <actuator name="gripper_base_to_gripper_left2_actuator">
      <hardwareInterface>hardware_interface/PositionJointInterface</hardwareInterface>
      <mechanicalReduction>1</mechanicalReduction>
    </actuator>
  </transmission>
  <!-- and so on for the remaining joints -->
  <transmission name="gripper_left3_to_gripper_left1_trans">
    <provideFeedback>true</provideFeedback>
    <type>transmission_interface/SimpleTransmission</type>
    <joint name="gripper_left3_to_gripper_left1">
      <hardwareInterface>hardware_interface/PositionJointInterface</hardwareInterface>
    </joint>
    <actuator name="gripper_left3_to_gripper_left1_actuator">
      <hardwareInterface>hardware_interface/PositionJointInterface</hardwareInterface>
      <mechanicalReduction>1</mechanicalReduction>
    </actuator>
  </transmission>
  <transmission name="gripper_base_to_gripper_right3_trans">
    <provideFeedback>true</provideFeedback>
    <type>transmission_interface/SimpleTransmission</type>
    <joint name="gripper_base_to_gripper_right3">
      <hardwareInterface>hardware_interface/PositionJointInterface</hardwareInterface>
    </joint>
    <actuator name="gripper_base_to_gripper_right3_actuator">
      <hardwareInterface>hardware_interface/PositionJointInterface</hardwareInterface>
      <mechanicalReduction>1</mechanicalReduction>
    </actuator>
  </transmission>
  <transmission name="gripper_base_to_gripper_right2_trans">
    <provideFeedback>true</provideFeedback>
    <type>transmission_interface/SimpleTransmission</type>
    <joint name="gripper_base_to_gripper_right2">
      <hardwareInterface>hardware_interface/PositionJointInterface</hardwareInterface>
    </joint>
    <actuator name="gripper_base_to_gripper_right2_actuator">
      <hardwareInterface>hardware_interface/PositionJointInterface</hardwareInterface>
      <mechanicalReduction>1</mechanicalReduction>
    </actuator>
  </transmission>
  <transmission name="gripper_right3_to_gripper_right1_trans">
    <provideFeedback>true</provideFeedback>
    <type>transmission_interface/SimpleTransmission</type>
    <joint name="gripper_right3_to_gripper_right1">
      <hardwareInterface>hardware_interface/PositionJointInterface</hardwareInterface>
    </joint>
    <actuator name="gripper_right3_to_gripper_right1_actuator">
      <hardwareInterface>hardware_interface/PositionJointInterface</hardwareInterface>
      <mechanicalReduction>1</mechanicalReduction>
    </actuator>
  </transmission>
</robot>

