<?xml version="1.0" ?>
<!-- =================================================================================== -->
<!-- |    This document was autogenerated by xacro from mycobot.urdf.xacro             | -->
<!-- |    EDITING THIS FILE BY HAND IS NOT RECOMMENDED                                 | -->
<!-- =================================================================================== -->
<robot name="mycobot">
  <link name="link1">
    <inertial>
      <origin rpy="0 0 0" xyz="0 0 0.035"/>
      <mass value="10.0"/>
      <inertia ixx="0.010333333333333335" ixy="0" ixz="0" iyy="0.010333333333333335" iyz="0" izz="0.0125"/>
    </inertial>
    <visual>
      <geometry>
        <mesh filename="package://mycobot_description/urdf/mycobot/mesh/link1.dae"/>
      </geometry>
      <origin rpy=" 0 0 -1.5707963267948966" xyz="0.0 0 0 "/>
    </visual>
    <collision>
      <geometry>
        <mesh filename="package://mycobot_description/urdf/mycobot/mesh/link1.dae"/>
      </geometry>
      <origin rpy=" 0 0 -1.5707963267948966" xyz="0.0 0 0 "/>
    </collision>
  </link>
  <link name="link2">
    <inertial>
      <origin rpy="0 0 0" xyz="0 0 0.060"/>
      <mass value="0.2"/>
      <inertia ixx="0.00023166666666666672" ixy="0" ixz="0" iyy="0.00023166666666666672" iyz="0" izz="0.00025000000000000006"/>
    </inertial>
    <visual>
      <geometry>
        <mesh filename="package://mycobot_description/urdf/mycobot/mesh/link2.dae"/>
      </geometry>
      <origin rpy=" 0 0 -1.5707963267948966" xyz="0.0 0 -0.06096 "/>
    </visual>
    <collision>
      <geometry>
        <mesh filename="package://mycobot_description/urdf/mycobot/mesh/link2.dae"/>
      </geometry>
      <origin rpy=" 0 0 -1.5707963267948966" xyz="0.0 0 -0.06096 "/>
    </collision>
  </link>
  <link name="link3">
    <inertial>
      <origin rpy="0 0 0" xyz="0.01 0 0.06"/>
      <mass value="0.4"/>
      <inertia ixx="0.0010508333333333335" ixy="0" ixz="0" iyy="0.0010508333333333335" iyz="0" izz="0.0005000000000000001"/>
    </inertial>
    <visual>
      <geometry>
        <mesh filename="package://mycobot_description/urdf/mycobot/mesh/link3.dae"/>
      </geometry>
      <origin rpy=" 0 -1.5707963267948966 0" xyz="0.0 0 0.03256 "/>
    </visual>
    <collision>
      <geometry>
        <mesh filename="package://mycobot_description/urdf/mycobot/mesh/link3.dae"/>
      </geometry>
      <origin rpy=" 0 -1.5707963267948966 0" xyz="0.0 0 0.03256 "/>
    </collision>
  </link>
  <link name="link4">
    <inertial>
      <origin rpy="0 0 0" xyz="-0.01 0 0.05"/>
      <mass value="0.4"/>
      <inertia ixx="0.0010508333333333335" ixy="0" ixz="0" iyy="0.0010508333333333335" iyz="0" izz="0.0005000000000000001"/>
    </inertial>
    <visual>
      <geometry>
        <!--- 0.0 0 -0.04 -->
        <mesh filename="package://mycobot_description/urdf/mycobot/mesh/link4.dae"/>
      </geometry>
      <origin rpy=" 0 -1.5707963267948966 0" xyz="0.0 0 0.03056 "/>
    </visual>
    <collision>
      <geometry>
        <!--- 0.0 0 -0.04 -->
        <mesh filename="package://mycobot_description/urdf/mycobot/mesh/link4.dae"/>
      </geometry>
      <origin rpy=" 0 -1.5707963267948966 0" xyz="0.0 0 0.03056 "/>
    </collision>
  </link>
  <link name="link5">
    <inertial>
      <origin rpy="0 0 0" xyz="0 0 0.05"/>
      <mass value="0.2"/>
      <inertia ixx="0.00016666666666666672" ixy="0" ixz="0" iyy="0.00016666666666666672" iyz="0" izz="0.00025000000000000006"/>
    </inertial>
    <visual>
      <geometry>
        <!--- 0.0 0 -0.04 -->
        <mesh filename="package://mycobot_description/urdf/mycobot/mesh/link5.dae"/>
      </geometry>
      <origin rpy=" -1.5707963267948966 0 0" xyz="0.0 0 -0.03356 "/>
    </visual>
    <collision>
      <geometry>
        <!--- 0.0 0 -0.04 -->
        <mesh filename="package://mycobot_description/urdf/mycobot/mesh/link5.dae"/>
      </geometry>
      <origin rpy=" -1.5707963267948966 0 0" xyz="0.0 0 -0.03356 "/>
    </collision>
  </link>
  <link name="link6">
    <inertial>
      <origin rpy="0 0 0" xyz="0 0 0.037"/>
      <mass value="0.5"/>
      <inertia ixx="0.0004625000000000001" ixy="0" ixz="0" iyy="0.0004625000000000001" iyz="0" izz="0.0006250000000000001"/>
    </inertial>
    <visual>
      <geometry>
        <!--- 0.0 0 -0.04 -->
        <mesh filename="package://mycobot_description/urdf/mycobot/mesh/link6.dae"/>
      </geometry>
      <origin rpy=" 0 0 0" xyz="0 0.00 -0.038 "/>
    </visual>
    <collision>
      <geometry>
        <!--- 0.0 0 -0.04 -->
        <mesh filename="package://mycobot_description/urdf/mycobot/mesh/link6.dae"/>
      </geometry>
      <origin rpy=" 0 0 0" xyz="0 0.00 -0.038 "/>
    </collision>
  </link>
  <link name="link7">
    <inertial>
      <origin rpy="1.570795 0 0" xyz="0 0.0025 0"/>
      <mass value="0.1"/>
      <inertia ixx="1.0208333333333334e-05" ixy="0" ixz="0" iyy="1.0208333333333334e-05" iyz="0" izz="2e-05"/>
    </inertial>
    <visual>
      <geometry>
        <!--- 0.0 0 -0.04 -->
        <mesh filename="package://mycobot_description/urdf/mycobot/mesh/link7.dae"/>
      </geometry>
      <origin rpy=" 0 0 0" xyz="0.0 0 -0.012 "/>
    </visual>
    <collision>
      <geometry>
        <!--- 0.0 0 -0.04 -->
        <mesh filename="package://mycobot_description/urdf/mycobot/mesh/link7.dae"/>
      </geometry>
      <origin rpy=" 0 0 0" xyz="0.0 0 -0.012 "/>
    </collision>
  </link>
  <link name="camera_link"/>
  <joint name="camera" type="fixed">
    <parent link="link1"/>
    <child link="camera_link"/>
    <origin rpy="0 0 0" xyz="0.36 0 0.57 "/>
  </joint>
  <joint name="joint1" type="revolute">
    <axis xyz="0 0 1"/>
    <limit effort="10.0" lower="-3.141592653589793" upper="3.141592653589793" velocity="1.0"/>
    <parent link="link1"/>
    <child link="link2"/>
    <origin rpy="0 0 0" xyz="0 0 0.13156"/>
    <dynamics damping="1.0e-6" friction="2.0e-1"/>
  </joint>
  <joint name="joint2" type="revolute">
    <axis xyz="0 0 1"/>
    <limit effort="10.0" lower="-3.141592653589793" upper="3.141592653589793" velocity="1.0"/>
    <parent link="link2"/>
    <child link="link3"/>
    <origin rpy="0 1.5707963267948966 -1.5707963267948966" xyz="0 0  0"/>
    <dynamics damping="1.0e-6" friction="2.0e-1"/>
  </joint>
  <joint name="joint3" type="revolute">
    <axis xyz=" 0 0 1"/>
    <limit effort="10.0" lower="-3.141592653589793" upper="3.141592653589793" velocity="1.0"/>
    <parent link="link3"/>
    <child link="link4"/>
    <origin rpy="0 0 0" xyz="-0.1104 0 0   "/>
    <dynamics damping="1.0e-6" friction="2.0e-1"/>
  </joint>
  <joint name="joint4" type="revolute">
    <axis xyz=" 0 0 1"/>
    <limit effort="10.0" lower="-3.141592653589793" upper="3.141592653589793" velocity="1.0"/>
    <parent link="link4"/>
    <child link="link5"/>
    <origin rpy="0 0 -1.5707963267948966" xyz="-0.096 0 0.06462"/>
    <dynamics damping="1.0e-6" friction="2.0e-1"/>
  </joint>
  <joint name="joint5" type="revolute">
    <axis xyz="0 0 1"/>
    <limit effort="10.0" lower="-3.141592653589793" upper="3.141592653589793" velocity="1.0"/>
    <parent link="link5"/>
    <child link="link6"/>
    <origin rpy="1.5707963267948966 -1.5707963267948966 0" xyz="0 -0.07318 0"/>
    <dynamics damping="1.0e-6" friction="2.0e-1"/>
  </joint>
  <joint name="joint6" type="revolute">
    <axis xyz="0 0 1"/>
    <limit effort="10.0" lower="-3.141592653589793" upper="3.141592653589793" velocity="1.0"/>
    <parent link="link6"/>
    <child link="link7"/>
    <origin rpy="-1.5707963267948966 0 0" xyz="0 0.0456 0"/>
    <dynamics damping="1.0e-6" friction="2.0e-1"/>
  </joint>
  <transmission name="joint1_trans">
    <provideFeedback>true</provideFeedback>
    <implicitSpringDamper>0</implicitSpringDamper>
    <motorTorqueConstant>0.418</motorTorqueConstant>
    <type>transmission_interface/SimpleTransmission</type>
    <joint name="joint1">
      <hardwareInterface>hardware_interface/PositionJointInterface</hardwareInterface>
    </joint>
    <actuator name="joint1_motor">
      <hardwareInterface>hardware_interface/PositionJointInterface</hardwareInterface>
      <mechanicalReduction>1</mechanicalReduction>
    </actuator>
  </transmission>
  <transmission name="joint2_trans">
    <provideFeedback>true</provideFeedback>
    <implicitSpringDamper>0</implicitSpringDamper>
    <motorTorqueConstant>0.418</motorTorqueConstant>
    <type>transmission_interface/SimpleTransmission</type>
    <joint name="joint2">
      <hardwareInterface>hardware_interface/PositionJointInterface</hardwareInterface>
    </joint>
    <actuator name="joint2_motor">
      <hardwareInterface>hardware_interface/PositionJointInterface</hardwareInterface>
      <mechanicalReduction>1</mechanicalReduction>
    </actuator>
  </transmission>
  <transmission name="joint3_trans">
    <provideFeedback>true</provideFeedback>
    <implicitSpringDamper>0</implicitSpringDamper>
    <motorTorqueConstant>0.418</motorTorqueConstant>
    <type>transmission_interface/SimpleTransmission</type>
    <joint name="joint3">
      <hardwareInterface>hardware_interface/PositionJointInterface</hardwareInterface>
    </joint>
    <actuator name="joint3_motor">
      <hardwareInterface>hardware_interface/PositionJointInterface</hardwareInterface>
      <mechanicalReduction>1</mechanicalReduction>
    </actuator>
  </transmission>
  <transmission name="joint4_trans">
    <provideFeedback>true</provideFeedback>
    <implicitSpringDamper>0</implicitSpringDamper>
    <motorTorqueConstant>0.418</motorTorqueConstant>
    <type>transmission_interface/SimpleTransmission</type>
    <joint name="joint4">
      <hardwareInterface>hardware_interface/PositionJointInterface</hardwareInterface>
    </joint>
    <actuator name="joint4_motor">
      <hardwareInterface>hardware_interface/PositionJointInterface</hardwareInterface>
      <mechanicalReduction>1</mechanicalReduction>
    </actuator>
  </transmission>
  <transmission name="joint5_trans">
    <provideFeedback>true</provideFeedback>
    <implicitSpringDamper>0</implicitSpringDamper>
    <motorTorqueConstant>0.418</motorTorqueConstant>
    <type>transmission_interface/SimpleTransmission</type>
    <joint name="joint5">
      <hardwareInterface>hardware_interface/PositionJointInterface</hardwareInterface>
    </joint>
    <actuator name="joint5_motor">
      <hardwareInterface>hardware_interface/PositionJointInterface</hardwareInterface>
      <mechanicalReduction>1</mechanicalReduction>
    </actuator>
  </transmission>
  <transmission name="joint6_trans">
    <provideFeedback>true</provideFeedback>
    <implicitSpringDamper>0</implicitSpringDamper>
    <motorTorqueConstant>0.418</motorTorqueConstant>
    <type>transmission_interface/SimpleTransmission</type>
    <joint name="joint6">
      <hardwareInterface>hardware_interface/PositionJointInterface</hardwareInterface>
    </joint>
    <actuator name="joint6_motor">
      <hardwareInterface>hardware_interface/PositionJointInterface</hardwareInterface>
      <mechanicalReduction>1</mechanicalReduction>
    </actuator>
  </transmission>
</robot>

